Workbook

Sheet 体育系
A1: 男：○ 女：△ 男女：□ | B1: 陸上競技 | C1: 水泳 | D1: 体操 | E1: 新体操 | F1: トランポリン | G1: ソフトボール | H1: バレーボール | I1: バスケットボール | J1: 硬式テニス | K1: ソフトテニス | L1: 卓球 | M1: ハンドボール | N1: バドミントン | O1: 剣道 | P1: アーチェリー | Q1: フェンシング | R1: 硬式野球 | S1: 軟式野球 | T1: サッカー | U1: フットサル | V1: 柔道 | W1: ウエイトリフティング | X1: 空手道 | Y1: 日本拳法 | Z1: ボクシング | AA1: 少林寺拳法 | AB1: 合気道 | AC1: テコンドー | AD1: レスリング | AE1: アメリカンフットボール | AF1: なぎなた | AG1: 弓道 | AH1: ラグビー | AI1: ゴルフ | AJ1: 自転車 | AK1: スキー | AL1: スケート | AM1: ラクロス | AN1: 登山(山岳) | AO1: ワンダーホーゲル | AP1: ダンス | AQ1: チアダンス
A2: 大阪星光学院高等学校 | B2: ○ | H2: ○ | I2: ○ | J2: ○ | L2: ○ | O2: ○ | R2: ○ | T2: ○ | V2: ○ | AG2: ○
A3: 興國 | B3: ○ | G3: ○ | H3: ○ | I3: ○ | J3: ○ | L3: ○ | O3: ○ | R3: ○ | S3: ○ | T3: ○ | V3: ○ | X3: ○ | Z3: ○ | AD3: ○ | AH3: ○ | AI3: ○ | AJ3: ○ | AM3: ○ | AP3: ○
A4: 清風 | B4: ○ | C4: ○ | D4: ○ | E4: ○ | H4: ○ | I4: ○ | J4: ○ | L4: ○ | M4: ○ | O4: ○ | T4: ○ | V4: ○ | X4: ○ | Y4: ○ | AE4: ○ | AI4: ○ | AP4: ○
A5: 東大阪大学柏原 | B5: ○ | H5: ○ | I5: ○ | L5: ○ | N5: ○ | R5: ○ | T5: ○ | V5: ○ | X5: ○ | Y5: ○ | AH5: ○ | AI5: ○
A6: 明星 | B6: ○ | C6: ○ | D6: ○ | H6: ○ | I6: ○ | K6: ○ | L6: ○ | O6: ○ | R6: ○ | T6: ○ | AO6: ○
A7: ヴェリタス城星学園 | C7: △ | J7: △ | N7: △ | O7: △ | AP7: △
A8: 大阪薫英女学院 | B8: △ | C8: △ | D8: △ | G8: △ | H8: △ | I8: △ | K8: △ | N8: △ | O8: △ | U8: △ | AP8: △
A9: 大阪女学院 | B9: △ | C9: △ | G9: △ | H9: △ | I9: △ | J9: △ | T9: △ | AG9: △ | AK9: △
A10: 大阪成蹊女子 | B10: △ | C10: △ | D10: △ | E10: △ | G10: △ | H10: △ | I10: △ | J10: △ | L10: △ | M10: △ | N10: △ | O10: △ | U10: △ | AP10: △ | AQ10: △
A11: 大谷 | B11: △ | H11: △ | I11: △ | J11: △ | L11: △ | M11: △ | N11: △ | AP11: △
A12: 香ヶ丘リベルテ | B12: △ | G12: △ | H12: △ | I12: △ | K12: △ | T12: △ | AP12: △
A13: 金蘭会 | E13: △ | G13: △ | H13: △ | I13: △ | J13: △ | N13: △ | O13: △ | X13: △ | AP13: △
A14: 好文学園女子 | H14: △ | I14: △ | K14: △ | M14: △ | O14: △ | AA14: △ | AG14: △ | AI14: △ | AP14: △
A15: 堺リベラル | I15: △ | J15: △ | AP15: △
A16: 四天王寺 | D16: △ | H16: △ | I16: △ | K16: △ | L16: △ | M16: △ | N16: △ | O16: △ | AB16: △ | AP16: △
A17: 樟蔭 | D17: △ | E17: △ | G17: △ | H17: △ | I17: △ | J17: △ | K17: △ | N17: △ | O17: △ | AP17: △
A18: 城南学園 | B18: △ | C18: △ | D18: △ | H18: △ | I18: △ | J18: △ | K18: △ | M18: △ | X18: △ | AG18: △ | AP18: △
A19: 宣真 | B19: △ | G19: △ | H19: △ | I19: △ | K19: △ | L19: △ | M19: △ | N19: △ | O19: △ | AF19: △
A20: 相愛 | B20: △ | D20: △ | E20: △ | H20: △ | I20: △ | J20: △ | K20: △ | O20: △
A21: 帝塚山学院 | B21: △ | C21: △ | F21: △ | H21: △ | I21: △ | K21: △ | N21: △ | O21: △ | P21: △ | T21: △ | AP21: △
A22: 梅花 | B22: △ | C22: △ | D22: △ | E22: △ | H22: △ | I22: △ | J22: △ | K22: △ | L22: △ | N22: △ | O22: △ | T22: △ | AP22: △
A23: プール学院 | B23: △ | D23: △ | G23: △ | H23: △ | I23: △ | K23: △ | L23: △ | N23: △ | AP23: △
A24: 藍野
A25: アサンプション国際
A26: アナン学園
A27: あべの翔学
A28: 上宮
A29: 上宮太子
A30: 英真学園
A31: 追手門学院
A32: 追手門学院大手前
A33: 大阪
A34: 大阪偕星学園
A35: 大阪学院大学
... A108: YMCA学院

Sheet Sheet3
A2: 大阪星光学院高等学校 | B2: =_xlfn.XLOOKUP(A2,hightSchoolData!$B$2:$B$379,hightSchoolData!$A$2:$A$379,"",1,1) -> 24 | C2: =_xlfn.XLOOKUP(A2,hightSchoolData!$B$2:$B$379,hightSchoolData!$B$2:$B$379,"",1,1) -> 大阪星光学院高等学校 | E2: =COUNTIF(B$2:B$108,B2) -> 1
A3: 興國 | B3: =_xlfn.XLOOKUP(A3,hightSchoolData!$B$2:$B$379,hightSchoolData!$A$2:$A$379,"",1,1) -> 50 | C3: =_xlfn.XLOOKUP(A3,hightSchoolData!$B$2:$B$379,hightSchoolData!$B$2:$B$379,"",1,1) -> 興國高等学校 | E3: =COUNTIF(B$2:B$108,B3) -> 1
A4: 清風 | B4: =_xlfn.XLOOKUP(A4,hightSchoolData!$B$2:$B$379,hightSchoolData!$A$2:$A$379,"",1,1) -> 71 | C4: =_xlfn.XLOOKUP(A4,hightSchoolData!$B$2:$B$379,hightSchoolData!$B$2:$B$379,"",1,1) -> 清風高等学校 | E4: =COUNTIF(B$2:B$108,B4) -> 1
A5: 東大阪大学柏原 | B5: =_xlfn.XLOOKUP(A5,hightSchoolData!$B$2:$B$379,hightSchoolData!$A$2:$A$379,"",1,1) -> 93 | C5: =_xlfn.XLOOKUP(A5,hightSchoolData!$B$2:$B$379,hightSchoolData!$B$2:$B$379,"",1,1) -> 東大阪大学柏原高等学校 | E5: =COUNTIF(B$2:B$108,B5) -> 1
A6: 明星 | B6: =_xlfn.XLOOKUP(A6,hightSchoolData!$B$2:$B$379,hightSchoolData!$A$2:$A$379,"",1,1) -> 100 | C6: =_xlfn.XLOOKUP(A6,hightSchoolData!$B$2:$B$379,hightSchoolData!$B$2:$B$379,"",1,1) -> 明星高等学校 | E6: =COUNTIF(B$2:B$108,B6) -> 1
A7: ヴェリタス城星学園 | B7: =_xlfn.XLOOKUP(A7,hightSchoolData!$B$2:$B$379,hightSchoolData!$A$2:$A$379,"",1,1) -> 5 | C7: =_xlfn.XLOOKUP(A7,hightSchoolData!$B$2:$B$379,hightSchoolData!$B$2:$B$379,"",1,1) -> ヴェリタス城星学園高等学校 | E7: =COUNTIF(B$2:B$108,B7) -> 1
A8: 大阪薫英女学院 | B8: =_xlfn.XLOOKUP(A8,hightSchoolData!$B$2:$B$379,hightSchoolData!$A$2:$A$379,"",1,1) -> 15 | C8: =_xlfn.XLOOKUP(A8,hightSchoolData!$B$2:$B$379,hightSchoolData!$B$2:$B$379,"",1,1) -> 大阪薫英女学院高等学校 | E8: =COUNTIF(B$2:B$108,B8) -> 1
A9: 大阪女学院 | B9: =_xlfn.XLOOKUP(A9,hightSchoolData!$B$2:$B$379,hightSchoolData!$A$2:$A$379,"",1,1) -> 21 | C9: =_xlfn.XLOOKUP(A9,hightSchoolData!$B$2:$B$379,hightSchoolData!$B$2:$B$379,"",1,1) -> 大阪女学院高等学校 | E9: =COUNTIF(B$2:B$108,B9) -> 1
A10: 大阪成蹊女子 | B10: =_xlfn.XLOOKUP(A10,hightSchoolData!$B$2:$B$379,hightSchoolData!$A$2:$A$379,"",1,1) -> 23 | C10: =_xlfn.XLOOKUP(A10,hightSchoolData!$B$2:$B$379,hightSchoolData!$B$2:$B$379,"",1,1) -> 大阪成蹊女子高等学校 | E10: =COUNTIF(B$2:B$108,B10) -> 1
A11: 大谷 | B11: =_xlfn.XLOOKUP(A11,hightSchoolData!$B$2:$B$379,hightSchoolData!$A$2:$A$379,"",1,1) -> 32 | C11: =_xlfn.XLOOKUP(A11,hightSchoolData!$B$2:$B$379,hightSchoolData!$B$2:$B$379,"",1,1) -> 大谷高等学校 | E11: =COUNTIF(B$2:B$108,B11) -> 1
A12: 香ヶ丘リベルテ | B12: =_xlfn.XLOOKUP(A12,hightSchoolData!$B$2:$B$379,hightSchoolData!$A$2:$A$379,"",1,1) -> 34 | C12: =_xlfn.XLOOKUP(A12,hightSchoolData!$B$2:$B$379,hightSchoolData!$B$2:$B$379,"",1,1) -> 香ヶ丘リベルテ高等学校 | E12: =COUNTIF(B$2:B$108,B12) -> 1
A13: 金蘭会 | B13: =_xlfn.XLOOKUP(A13,hightSchoolData!$B$2:$B$379,hightSchoolData!$A$2:$A$379,"",1,1) -> 45 | C13: =_xlfn.XLOOKUP(A13,hightSchoolData!$B$2:$B$379,hightSchoolData!$B$2:$B$379,"",1,1) -> 金蘭会高等学校 | E13: =COUNTIF(B$2:B$108,B13) -> 1
... A23: プール学院 | B23: =_xlfn.XLOOKUP(A23,hightSchoolData!$B$2:$B$379,hightSchoolData!$A$2:$A$379,"",1,1) -> 96 | C23: =_xlfn.XLOOKUP(A23,hightSchoolData!$B$2:$B$379,hightSchoolData!$B$2:$B$379,"",1,1) -> プール学院高等学校 | E23: =COUNTIF(B$2:B$108,B23) -> 1
E24: =COUNTIF(B$2:B$108,B24) -> 1
A25: アサンプション国際 | B25: =_xlfn.XLOOKUP(A25,hightSchoolData!$B$2:$B$379,hightSchoolData!$A$2:$A$379,"",1,1) -> 0 | C25: =_xlfn.XLOOKUP(A25,hightSchoolData!$B$2:$B$379,hightSchoolData!$B$2:$B$379,"",1,1) -> アサンプション国際高等学校 | E25: =COUNTIF(B$2:B$108,B25) -> 1
A26: アナン学園 | B26: =_xlfn.XLOOKUP(A26,hightSchoolData!$B$2:$B$379,hightSchoolData!$A$2:$A$379,"",1,1) -> 1 | C26: =_xlfn.XLOOKUP(A26,hightSchoolData!$B$2:$B$379,hightSchoolData!$B$2:$B$379,"",1,1) -> アナン学園高等学校 | E26: =COUNTIF(B$2:B$108,B26) -> 1
A27: あべの翔学 | B27: =_xlfn.XLOOKUP(A27,hightSchoolData!$B$2:$B$379,hightSchoolData!$A$2:$A$379,"",1,1) -> 2 | C27: =_xlfn.XLOOKUP(A27,hightSchoolData!$B$2:$B$379,hightSchoolData!$B$2:$B$379,"",1,1) -> あべの翔学高等学校 | E27: =COUNTIF(B$2:B$108,B27) -> 1
A28: 上宮 | B28: =_xlfn.XLOOKUP(A28,hightSchoolData!$B$2:$B$379,hightSchoolData!$A$2:$A$379,"",1,1) -> 3 | C28: =_xlfn.XLOOKUP(A28,hightSchoolData!$B$2:$B$379,hightSchoolData!$B$2:$B$379,"",1,1) -> 上宮高等学校 | E28: =COUNTIF(B$2:B$108,B28) -> 1
A29: 上宮太子 | B29: =_xlfn.XLOOKUP(A29,hightSchoolData!$B$2:$B$379,hightSchoolData!$A$2:$A$379,"",1,1) -> 4 | C29: =_xlfn.XLOOKUP(A29,hightSchoolData!$B$2:$B$379,hightSchoolData!$B$2:$B$379,"",1,1) -> 上宮太子高等学校 | E29: =COUNTIF(B$2:B$108,B29) -> 1
A30: 英真学園 | B30: =_xlfn.XLOOKUP(A30,hightSchoolData!$B$2:$B$379,hightSchoolData!$A$2:$A$379,"",1,1) -> 6 | C30: =_xlfn.XLOOKUP(A30,hightSchoolData!$B$2:$B$379,hightSchoolData!$B$2:$B$379,"",1,1) -> 英真学園高等学校 | E30: =COUNTIF(B$2:B$108,B30) -> 1
A31: 追手門学院 | B31: =_xlfn.XLOOKUP(A31,hightSchoolData!$B$2:$B$379,hightSchoolData!$A$2:$A$379,"",1,1) -> 8 | C31: =_xlfn.XLOOKUP(A31,hightSchoolData!$B$2:$B$379,hightSchoolData!$B$2:$B$379,"",1,1) -> 追手門学院高等学校 | E31: =COUNTIF(B$2:B$108,B31) -> 1
A32: 追手門学院大手前 | B32: =_xlfn.XLOOKUP(A32,hightSchoolData!$B$2:$B$379,hightSchoolData!$A$2:$A$379,"",1,1) -> 9 | C32: =_xlfn.XLOOKUP(A32,hightSchoolData!$B$2:$B$379,hightSchoolData!$B$2:$B$379,"",1,1) -> 追手門学院大手前高等学校 | E32: =COUNTIF(B$2:B$108,B32) -> 1
A33: 大阪高等 | B33: =_xlfn.XLOOKUP(A33,hightSchoolData!$B$2:$B$379,hightSchoolData!$A$2:$A$379,"",1,1) -> 10 | C33: =_xlfn.XLOOKUP(A33,hightSchoolData!$B$2:$B$379,hightSchoolData!$B$2:$B$379,"",1,1) -> 大阪高等学校 | E33: =COUNTIF(B$2:B$108,B33) -> 1
A34: 大阪偕星学園 | B34: =_xlfn.XLOOKUP(A34,hightSchoolData!$B$2:$B$379,hightSchoolData!$A$2:$A$379,"",1,1) -> 11 | C34: =_xlfn.XLOOKUP(A34,hightSchoolData!$B$2:$B$379,hightSchoolData!$B$2:$B$379,"",1,1) -> 大阪偕星学園高等学校 | E34: =COUNTIF(B$2:B$108,B34) -> 1
A35: 大阪学院大学 | B35: =_xlfn.XLOOKUP(A35,hightSchoolData!$B$2:$B$379,hightSchoolData!$A$2:$A$379,"",1,1) -> 12 | C35: =_xlfn.XLOOKUP(A35,hightSchoolData!$B$2:$B$379,hightSchoolData!$B$2:$B$379,"",1,1) -> 大阪学院大学高等学校 | E35: =COUNTIF(B$2:B$108,B35) -> 1
A36: 大阪学芸 | B36: =_xlfn.XLOOKUP(A36,hightSchoolData!$B$2:$B$379,hightSchoolData!$A$2:$A$379,"",1,1) -> 13 | C36: =_xlfn.XLOOKUP(A36,hightSchoolData!$B$2:$B$379,hightSchoolData!$B$2:$B$379,"",1,1) -> 大阪学芸高等学校 | E36: =COUNTIF(B$2:B$108,B36) -> 1
... A108: YMCA学院 | B108: =_xlfn.XLOOKUP(A108,hightSchoolData!$B$2:$B$379,hightSchoolData!$A$2:$A$379,"",1,1) -> 104 | C108: =_xlfn.XLOOKUP(A108,hightSchoolData!$B$2:$B$379,hightSchoolData!$B$2:$B$379,"",1,1) -> YMCA学院高等学校 | E108: =COUNTIF(B$2:B$108,B108) -> 1

Sheet 文化系
A1: 男：○ 女：△ 男女：□ | B1: 音楽 | C1: 合唱・コーラス | D1: 聖歌隊 | E1: ハンドベル | F1: 吹奏楽 | G1: 軽音楽 | H1: フォークソング | I1: ギター | J1: クラッシックギター | K1: マンドリン | L1: 箏曲 | M1: 和太鼓 | N1: 日舞 | O1: バトントワリング | P1: チアリーディング | Q1: 演劇 | R1: 美術 | S1: 書道 | T1: 写真 | U1: 茶道 | V1: 華道 | W1: 茶華道 | X1: 新聞 | Y1: 放送 | Z1: 映画研究 | AA1: マンガ研究 | AB1: アニメーション | AC1: クイズ研究 | AD1: 歴史研究 | AE1: イラスト | AF1: 囲碁 | AG1: 囲碁将棋 | AH1: 将棋 | AI1: かるた | AJ1: 文芸 | AK1: 図書 | AL1: 釣り | AM1: 理科 | AN1: 科学(サイエンス) | AO1: 生物 | AP1: 園芸 | AQ1: 化学 | AR1: 地歴 | AS1: 人権問題研究 | AT1: ボランティア | AU1: インターアクト | AV1: YMCA | AW1: 手話 | AX1: 食物(調理) | AY1: 鉄道研究 | AZ1: ESS | BA1: 英語(英会話) | BB1: 簿記 | BC1: コンピュータ(パソコン) | BD1: eスポーツ
A2: 大阪星光学院高等学校
A3: 興國
A4: 清風
A5: 東大阪大学柏原
A6: 明星
A7: ヴェリタス城星学園
A8: 大阪薫英女学院
A9: 大阪女学院
A10: 大阪成蹊女子
A11: 大谷
A12: 香ヶ丘リベルテ
A13: 金蘭会
... A108: YMCA学院

Sheet hightSchoolData
A1: id | B1: name | C1: ruby | D1: site | E1: address | F1: label | G1: education | H1: course | I1: tel | J1: lat | K1: lng | L1: near | M1: course1 | N1: course2 | O1: course3 | P1: course4 | Q1: course5 | R1: course6
A2: 0 | B2: アサンプション国際高等学校 | C2: あさんぷしょんこくさいこうとうがっこう | D2: https://www.assumption.ed.jp/jsh/ | E2: 大阪府箕面市如意谷1-13-23 | F2: 私立 | G2: 共学校 | H2: 普通科 | I2: 072-721-3080 | J2: 34.836591 | K2: 135.47868 | L2: 阪急箕面線「箕面」徒歩約15分／阪急千里線「北千里」からスクールバス／北大阪急行・大阪モノレール「千里中央」から阪急バス「如意谷住宅前」下車徒歩約2分・「第二中学校口」下車徒歩約5分 | M2: 普通科
A3: 1 | B3: アナン学園高等学校 | C3: あなんがくえんこうとうがっこう | D3: https://www.anangakuen.ed.jp/ | E3: 大阪府東大阪市若江西新町3-1-8 | F3: 私立 | G3: 共学校 | H3: 看護科（5年一貫教育）、調理科 | I3: 06-6723-5511 | J3: 34.656545 | K3: 135.59693 | L3: 近鉄奈良線「八戸野ノ里」南東徒歩約15分 | M3: 看護科（5年一貫教育） | N3: 調理科
A4: 2 | B4: あべの翔学高等学校 | C4: あべのしょうまなぶこうとうがっこう | D4: http://www.abeno-shogaku.ed.jp | E4: 大阪府大阪市阿倍野区天王寺町南2-8-19 | F4: 私立 | G4: 共学校 | H4: 普通科 | I4: 06-6719-2801 | J4: 34.642423 | K4: 135.52533 | L4: 近鉄南大阪線「河堀口」180ｍ／JR阪和線「美章園」600ｍ／JR環状線「寺田町」700ｍ | M4: 普通科
A5: 3 | B5: 上宮高等学校 | C5: うえみやこうとうがっこう | D5: http://www.uenomiya.ed.jp | E5: 大阪府大阪市天王寺区上之宮町9-36 | F5: 私立 | G5: 共学校 | H5: 普通科 | I5: 06-6771-5701 | J5: 34.661188 | K5: 135.51968 | L5: 大阪メトロ谷町線・千日前線「谷町九丁目」徒歩10分／JR大阪環状線「桃谷」徒歩12分／近鉄「大阪上本町」徒歩6分／大阪市バス62号系統「上本町八丁目」下車徒歩2分 | M5: 普通科
A6: 4 | B6: 上宮太子高等学校 | C6: うえのみやたいしこうとうがっこう | D6: http://www.uenomiya-taishi.ed.jp | E6: 大阪府大阪府南河内郡太子町太子1053 | F6: 私立 | G6: 共学校 | H6: 普通科 | I6: 0721-98-3611 | J6: 34.51615 | K6: 135.63741 | L6: 近鉄長野線「喜志」・近鉄南大阪線「上ノ太子」・JR大和路線「高井田」・近鉄大阪線「河内国分」・南海高野線「金剛」からスクールバス | M6: 普通科
A7: 5 | B7: ヴェリタス城星学園高等学校 | C7: う゛ぇりたすじょうせいがくえんこうとうがっこう | D7: http://www.josei.ed.jp/ | E7: 大阪府大阪市中央区玉造2-23-26 | F7: 私立 | G7: 女子校 | H7: 普通科 | I7: 06-6941-5977 | J7: 34.678156 | K7: 135.52797 | L7: JR環状線「玉造」・「森ノ宮」徒歩約10分／大阪メトロ「玉造」徒歩約6分／大阪メトロ「森ノ宮」徒歩約10分／大阪市バス「玉造二丁目」下車徒歩約3分 | M7: 普通科
A8: 6 | B8: 英真学園高等学校 | C8: えいしんがくえんこうとうがっこう | D8: http://www.eishingakuen.ac.jp | E8: 大阪府大阪市淀川区十三東5-4-38 | F8: 私立 | G8: 共学校 | H8: 普通科 | I8: 06-6303-2181 | J8: 34.723726 | K8: 135.48344 | L8: 阪急「十三」東口徒歩5分 | M8: 普通科
A9: 7 | B9: 英風高等学校 | C9: えいふうこうとうがっこう | D9: https://eifu.ed.jp/ | E9: 大阪府大阪市福島区吉野4-13-4 | F9: 私立 | G9: 女子校 | H9: 通信制 | I9: 0120-8120-78 | J9: 34.688457 | K9: 135.47162 | L9: JR環状線「野田」徒歩約3分／JR東西線「海老江」徒歩約13分／大阪メトロ千日前線「玉川」徒歩約5分／阪神本線「野田」徒歩約13分 | M9: 通信制
A10: 8 | B10: 追手門学院高等学校 | C10: おうてもんがくいんこうとうがっこう | D10: https://www.otemon-jh.ed.jp | E10: 大阪府茨木市太田東芝町1-1 | F10: 私立 | G10: 共学校 | H10: 普通科 | I10: 072-697-8185 | J10: 34.838221 | K10: 135.57717 | L10: JR京都線「総持寺」徒歩15分／阪急京都線「総持寺」徒歩25分／阪急京都線「茨木市」から近鉄バス「追大総持寺キャンパス前」・「追手門学院中・高前」下車すぐ | M10: 普通科
A11: 9 | B11: 追手門学院大手前高等学校 | C11: おうてもんがくいんおおてまえこうとうがっこう | D11: https://www.otemon-js.ed.jp/ | E11: 大阪府大阪市中央区大手前1-3-20 | F11: 私立 | G11: 共学校 | H11: 普通科 | I11: 06-6942-2235 | J11: 34.689318 | K11: 135.5207 | L11: 京阪本線・大阪メトロ谷町線「天満橋」徒歩5分／JR東西線「大阪城北詰」徒歩10分 | M11: 普通科
A12: 10 | B12: 大阪高等学校 | C12: おおさかこうとうがっこう | D12: http://www.osakashs.ed.jp/ | E12: 大阪府大阪市東淀川区相川2-18-51 | F12: 私立 | G12: 共学校 | H12: 普通科 | I12: 06-6340-3031 | J12: 34.759083 | K12: 135.53495 | L12: 阪急京都線「相川」徒歩すぐ／JR京都線「吹田」下車徒歩15分／大阪メトロ今里筋線「井高野」徒歩12分 | M12: 普通科
A13: 11 | B13: 大阪偕星学園高等学校 | C13: おおさかかいせいがくえんこうとうがっこう | D13: http://www.osaka-kaisei.ac.jp | E13: 大阪府大阪市生野区勝山南2-6-38 | F13: 私立 | G13: 共学校 | H13: 普通科 | I13: 06-6716-0003 | J13: 34.65255 | K13: 135.53017 | L13: JR大阪環状線「桃谷」「寺田町」徒歩10分 | M13: 普通科
A14: 12 | B14: 大阪学院大学高等学校 | C14: おおさかがくいんだいがくこうとうがっこう | D14: http://www.ogu-h.ed.jp/ | E14: 大阪府吹田市岸辺南2-6-1 | F14: 私立 | G14: 共学校 | H14: 普通科 | I14: 06-6381-6661 | J14: 34.774764 | K14: 135.54137 | L14: JR京都線「岸辺」徒歩2分／阪急京都線「正雀」徒歩7分 | M14: 普通科
A15: 13 | B15: 大阪学芸高等学校 | C15: おおさかがくげいこうとうがっこう | D15: https://www.osakagakugei.ac.jp/senior/ | E15: 大阪府大阪市住吉区長居1-4-15 | F15: 私立 | G15: 共学校 | H15: 普通科 | I15: 06-6693-6301 | J15: 34.61537 | K15: 135.51212 | L15: JR阪和線「長居」徒歩6分、JR阪和線「鶴ヶ丘」徒歩8分、大阪メトロ御堂筋線「長居」徒歩7分、大阪メトロ御堂筋線「西田辺」徒歩10分 | M15: 普通科
A16: 14 | B16: 大阪暁光高等学校 | C16: おおさかぎょうこうこうとうがっこう | D16: https://www.osakagyoko.ed.jp/ | E16: 大阪府河内長野市楠町西1090 | F16: 私立 | G16: 共学校 | H16: 看護科、看護専攻科、普通科 | I16: 0721-53-5281 | J16: 34.470816 | K16: 135.5611 | L16: 南海高野線「千代田」北西徒歩8分 | M16: 看護科 | N16: 看護専攻科 | O16: 普通科
A17: 15 | B17: 大阪薫英女学院高等学校 | C17: おおさかくんえいじょがくいんこうとうがっこう | D17: https://www.kun-ei.jp/ | E17: 大阪府摂津市正雀1-4-1 | F17: 私立 | G17: 女子校 | H17: 国際科、普通科 | I17: 06-6381-5381 | J17: 34.778372 | K17: 135.54993 | L17: 阪急京都線「正雀」徒歩5分／JR「岸辺」徒歩10分／大阪モノレール「摂津」徒歩15分 | M17: 国際科 | N17: 普通科
A18: 16 | B18: 大阪国際高等学校 | C18: おおさかこくさいこうとうがっこう | D18: https://www.kokusai-h.oiu.ed.jp | E18: 大阪府守口市松下町1-28 | F18: 私立 | G18: 共学校 | H18: 普通科 | I18: 06-6992-5931 | J18: 34.72952 | K18: 135.56767 | L18: 京阪「土居」徒歩8分・京阪「守口」徒歩10分・今里筋線「清水」徒歩12分・谷町線「太子橋今市」徒歩14分・大阪シティバス「滝井」徒歩7分 | M18: 普通科
A19: 17 | B19: 大阪金剛インターナショナル高等学校 | C19: おおさかこんごういんたーなしょなるこうとうがっこう | D19: http://www.kongogakuen.ed.jp | E19: 大阪府大阪市住之江区南港北2-6-10 | F19: 私立 | G19: 共学校 | H19: 普通科 | I19: 06-4703-1780 | J19: 34.639535 | K19: 135.40734 | L19: 大阪メトロ中央線「コスモスクエア」徒歩15分／ニュートラム「トレードセンター前」徒歩7分 | M19: 普通科
A20: 18 | B20: 大阪産業大学附属高等学校 | C20: おおさかさんぎょうだいがくふぞくこうとうがっこう | D20: http://www.osaka-sandai.ed.jp/ | E20: 大阪府大阪市城東区古市1-20-26 | F20: 私立 | G20: 共学校 | H20: 国際科、普通科 | I20: 06-6939-1491 | J20: 34.708851 | K20: 135.55892 | L20: 大阪メトロ長堀鶴見緑地線「今福鶴見」徒歩7分／大阪メトロ今里筋線「新森古市」徒歩7分／京阪本線「関目」徒歩15分／大阪市シティバス86号系統「鶴見六丁目」下車すぐ | M20: 国際科 | N20: 普通科
A21: 19 | B21: 大阪商業大学高等学校 | C21: おおさかしょうぎょうだいがくこうとうがっこう | D21: http://www.daishodai-h.ed.jp | E21: 大阪府東大阪市御厨栄町4-1-10 | F21: 私立 | G21: 共学校 | H21: 普通科 | I21: 06-6781-3050 | J21: 34.666876 | K21: 135.58573 | L21: 近鉄奈良線「八戸ノ里」徒歩4分・「河内小阪」北東徒歩8分／大阪メトロ中央線「長田」徒歩20分／JR学研都市線「徳庵」からバス「商業大学前」・「鴻池新田」からバス「商業大学前」下車すぐ | M21: 普通科
A22: 20 | B22: 大阪商業大学堺高等学校 | C22: おおさかしょうぎょうだいがくさかいこうとうがっこう | D22: http://www.shodaisakai.ac.jp | E22: 大阪府堺市中区堀上町358 | F22: 私立 | G22: 共学校 | H22: 普通科 | I22: 072-278-2252 | J22: 34.528067 | K22: 135.48699 | L22: JR「津久野」からバス「八田寺公園前」または「堀上」下車すぐ／泉北高速鉄道「深井」下車徒歩15分 | M22: 普通科
A23: 21 | B23: 大阪女学院高等学校 | C23: おおさかじょがくいんこうとうがっこう | D23: http://www.osaka-jogakuin.ed.jp | E23: 大阪府大阪市中央区玉造2-26-54 | F23: 私立 | G23: 女子校 | H23: 英語科、普通科 | I23: 06-6761-4113 | J23: 34.675871 | K23: 135.52767 | L23: 大阪メトロ長堀鶴見緑地線「玉造」1番出口西徒歩3分／JR環状線「玉造」西500ｍ／大阪メトロ中央線「森ノ宮」南西700ｍ／大阪市バス「清水谷高校前」下車北100ｍ | M23: 英語科 | N23: 普通科
A24: 22 | B24: 大阪信愛学院高等学校 | C24: おおさかしんあいがくいんこうとうがっこう | D24: http://www.osaka-shinai.ac.jp | E24: 大阪府大阪市城東区古市2-7-30 | F24: 私立 | G24: 共学校 | H24: 普通科 | I24: 06-6939-4391 | J24: 34.711171 | K24: 135.55776 | L24: 京阪本線「関目」徒歩15分、大阪メトロ長堀鶴見緑地線「今福鶴見」徒歩15分、大阪メトロ谷町線「関目高殿」徒歩18分、大阪メトロ今里筋線「新森古市」徒歩5分 | M24: 普通科
A25: 23 | B25: 大阪成蹊女子高等学校 | C25: おおさかせいけいじょしこうとうがっこう | D25: http://high.osaka-seikei.ac.jp | E25: 大阪府大阪市東淀川区相川3-10-62 | F25: 私立 | G25: 女子校 | H25: 美術科、普通科 | I25: 06-6829-2510 | J25: 34.759108 | K25: 135.53747 | L25: 阪急京都線「相川」東徒歩約4分／大阪メトロ今里筋線・JR京都線「吹田」からスクールバス | M25: 美術科 | N25: 普通科
A26: 24 | B26: 大阪星光学院高等学校 | C26: おおさかせいこうがくいんこうとうがっこう | D26: http://www.osakaseiko.ac.jp/ | E26: 大阪府大阪市天王寺区伶人町1-6 | F26: 私立 | G26: 男子校 | H26: 普通科 | I26: 06-6771-0737 | J26: 34.656462 | K26: 135.51334 | L26: 大阪メトロ谷町線「四天王寺前夕陽丘」徒歩2分 | M26: 普通科
A27: 25 | B27: 大阪青凌高等学校 | C27: おおさかせいりょうこうとうがっこう | D27: https://www.osakaseiryo.jp/ | E27: 大阪府三島郡島本町若山台1-1-1 | F27: 私立 | G27: 共学校 | H27: 普通科 | I27: 075-754-7771 | J27: 34.886652 | K27: 135.6605 | L27: JR京都線「島本」徒歩10分／阪急京都線「水無瀬」徒歩15分 | M27: 普通科
A28: 26 | B28: 大阪体育大学浪商高等学校 | C28: おおさかたいいくだいがくなみしょうこうとうがっこう | D28: http://www.ouhs-school.jp/ | E28: 大阪府大阪府泉南郡熊取町朝代台1-1 | F28: 私立 | G28: 共学校 | H28: 普通科 | I28: 072-453-7001 | J28: 34.380295 | K28: 135.35724 | L28: JR阪和線「熊取」から南海バス「浪商学園前」下車／南海本線「泉佐野」から南海バス「浪商学園前」下車 | M28: 普通科
A29: 27 | B29: 大阪つくば開成高等学校 | C29: おおさかつくばかいせいこうとうがっこう | D29: http://otk.ed.jp/ | E29: 大阪府大阪市北区天満2-2-16 | F29: 私立 | G29: 共学校 | H29: 通信制 | I29: 06-6352-0020 | J29: 34.692333 | K29: 135.51634 | L29: 京阪・大阪メトロ谷町線「天満橋」徒歩4分／JR東西線「大阪天満宮」・大阪メトロ堺筋線「南森町」JR2番出口徒歩9分 | M29: 通信制
A30: 28 | B30: 大阪電気通信大学高等学校 | C30: おおさかでんきつうしんだいがくこうとうがっこう | D30: http://www.dentsu.ed.jp/ | E30: 大阪府守口市橋波西之町1-5-18 | F30: 私立 | G30: 共学校 | H30: 工学科、普通科 | I30: 06-6992-6261 | J30: 34.737075 | K30: 135.57142 | L30: 京阪電車「守口市」徒歩10分／京阪電車「西三荘」徒歩6分／大阪モノレール・京阪電車「門真市」徒歩16分／大阪メトロ谷町線「守口」徒歩10分 | M30: 工学科 | N30: 普通科
A31: 29 | B31: 大阪桐蔭高等学校 | C31: おおさかとういんこうとうがっこう | D31: http://www.osakatoin.ed.jp | E31: 大阪府大東市中垣内3-1-1 | F31: 私立 | G31: 共学校 | H31: 普通科 | I31: 072-870-1001 | J31: 34.707958 | K31: 135.64566 | L31: JR学研都市線「野崎」徒歩18分・「住道」からシャトルバス／近鉄けいはんな線「新石切」から近鉄バス「産業大学前」下車すぐ | M31: 普通科
A32: 30 | B32: 大阪夕陽丘学園高等学校 | C32: おおさかゆうひがおかがくえんこうとうがっこう | D32: http://www.oyg.ed.jp | E32: 大阪府大阪市天王寺区生玉寺町7-72 | F32: 私立 | G32: 共学校 | H32: 普通科 | I32: 06-6771-9510 | J32: 34.659836 | K32: 135.5135 | L32: 大阪メトロ谷町線「四天王寺前夕陽ヶ丘」徒歩3分／南海「なんば」徒歩12分／近鉄「大阪上本町」徒歩12分／JR「天王寺」徒歩20分 | M32: 普通科
A33: 31 | B33: 大阪緑涼高等学校 | C33: おおさかりょくりょうこうとうがっこう | D33: http://www.osakaryokuryo.ed.jp/ | E33: 大阪府藤井寺市春日丘3-8-1 | F33: 私立 | G33: 共学校 | H33: 普通科 | I33: 072-955-0718 | J33: 34.569304 | K33: 135.58956 | L33: 近鉄南大阪線「藤井寺」徒歩5分 | M33: 普通科
A34: 32 | B34: 大谷高等学校 | C34: おおたにこうとうがっこう | D34: http://www.osk-ohtani.ed.jp | E34: 大阪府大阪市阿倍野区共立通2-8-4 | F34: 私立 | G34: 女子校 | H34: 普通科 | I34: 06-6661-8400 | J34: 34.638967 | K34: 135.50622 | L34: 大阪メトロ谷町線「阿倍野」徒歩8分／JR環状線・阪和線「天王寺」・近鉄南大阪線「あべの橋」・大阪メトロ御堂筋線「天王寺」徒歩17分／南海本線・高野線・大阪メトロ堺筋線「天下茶屋」徒歩15分／阪堺線「松虫」徒歩7分 | M34: 普通科
A35: 33 | B35: 開明高等学校 | C35: かいめいこうとうがっこう | D35: https://www.kaimei.ed.jp/ | E35: 大阪府大阪市城東区野江1-9-9 | F35: 私立 | G35: 共学校 | H35: 普通科 | I35: 06-6932-4461 | J35: 34.700955 | K35: 135.53781 | L35: 大阪メトロ谷町線「野江内代」、大阪メトロ長堀鶴見緑地線・今里筋線「蒲生四丁目」、京阪本線「野江」、JRおおさか東線「JR野江」徒歩12分 | M35: 普通科
A36: 34 | B36: 香ヶ丘リベルテ高等学校 | C36: かおりがおかりべるてこうとうがっこう | D36: http://www.liberte.ed.jp | E36: 大阪府堺市堺区浅香山町1-2-20 | F36: 私立 | G36: 女子校 | H36: 普通科 | I36: 072-238-7881 | J36: 34.584265 | K36: 135.49742 | L36: JR阪和線「浅香」徒歩5分／南海高野線「浅香山」徒歩12分／大阪メトロ御堂筋線「北花田」からバス「愛泉学園前」下車 | M36: 普通科
A37: 35 | B37: 関西大倉高等学校 | C37: かんさいおおくらこうとうがっこう | D37: http://www.kankura.jp | E37: 大阪府茨木市室山2-14-1 | F37: 私立 | G37: 共学校 | H37: 普通科 | I37: 072-643-6321 | J37: 34.848608 | K37: 135.54207 | L37: JR「茨木」／阪急「茨木市」「北千里」「石橋阪大前」／北大阪急行・大阪モノレール「千里中央」からスクールバス | M37: 普通科
A38: 36 | B38: 関西創価高等学校 | C38: かんさいそうかこうとうがっこう | D38: http://www.kansai.soka.ed.jp | E38: 大阪府交野市寺3-20-1 | F38: 私立 | G38: 共学校 | H38: 普通科 | I38: 072-891-0011 | J38: 34.78444 | K38: 135.69727 | L38: JR学研都市線「河内磐船」徒歩20分・京阪交野線「河内森」徒歩20分 | M38: 普通科
A39: 37 | B39: 関西大学高等部 | C39: かんさいだいがくこうとうぶ | D39: https://www.kansai-u.ac.jp/senior/ | E39: 大阪府大阪府高槻市白梅町7-1 | F39: 私立 | G39: 共学校 | H39: 普通科 | I39: 072-684-4327 | J39: 34.85493 | K39: 135.62264 | L39: JR京都線「高槻」徒歩7分／阪急京都線「高槻市」徒歩10分 | M39: 普通科
A40: 38 | B40: 関西大学第一高等学校 | C40: かんさいだいがくだいいちこうとうがっこう | D40: http://www.kansai-u.ac.jp/dai-ichi/high/ | E40: 大阪府吹田市山手町3-3-24 | F40: 私立 | G40: 共学校 | H40: 普通科 | I40: 06-6337-7750 | J40: 34.770101 | K40: 135.50906 | L40: 阪急千里線「関大前」南徒歩3分 | M40: 普通科
...
